Workbook

Sheet Month summary
A1: Weekly total (grocery, weekend) | E1: =sum(C2:C6) -> 1563.4
A2: Week 1 | B2: 30th Mar - 5th Apr | C2: =sum('Week 1'!H24) -> 397.3
A3: Week 2 | B3: 6th Apr - 12th Apr | C3: =sum('Week 2'!H24) -> 333.91
A4: Week 3 | B4: 13th Apr - 19th Apr | C4: =sum('Week 3'!H21) -> 312.41
A5: Week 4 | B5: 20th Apr - 26th Apr | C5: =sum('Week 4'!H28) -> 278.52
A6: Week 5 | B6: 27th Apr - 3rd May | C6: =sum('Week 5'!H28) -> 241.26 | G6: Total weekly | H6: =sum(C2:C6) -> 1563.4
G7: GBP budgetted | H7: 1300
A8: Bills | E8: =sum(C9:C29) -> 3578.62 | G8: GBP left | H8: =minus(H7,H6) -> -263.4
A9: Council tax | C9: 236.64 | G9: GBP left
A10: Green Energy | C10: 111.24
A11: Insite | C11: 111.2
A12: SES Water | B12: Payment 2/2 380.77 - 227 paid last month, this month: 153.77 | C12: 0 | G12: All transport | H12: =sum('Week 1'!C58,'Week 2'!C54,'Week 3'!C57,'Week 4'!C57) -> 104.66
A13: iTunes 2TB | B13: 20th of the month | C13: 8.99 | G13: GBP budgetted | H13: 300
A14: Savings | C14: 50 | G14: GBP left | H14: =minus(H13,H12) -> 195.34
A15: Huel | C15: 45
A16: HyperOptic | B16: Change in billing cycle | C16: 39
A17: Sutton Barbers | B17: mo and adam 18 apr | C17: 47
A18: Blike | B18: Bike subscription | C18: 156.09 | G18: Grand total | H18: =SUM(H6,C9:C30,C32:C161) -> 6378.1
A19: Rent | B19: t0030640 (90012335 - 93CT Amer) | C19: 2325 | G19: Salary GBP | H19: 6938.03
A20: Little Kickers | C20: 46 | G20: Salary GBP left actual | H20: =minus(H19,H18) -> 559.93
A21: Dragonflies | B21: 975.68 div 2 (Nadia paid 772) | C21: 203.68
A22: Voxi | B22: Beginning November 10 | C22: 10
A23: HMRC | B23: Paying for self assessment 22-23 | C23: 0
A24: Spotify | B24: 8th of April | C24: 16.99 | G24: End of month forecast total | H24: =SUM(H18,if((H8)<0, 0, (H8))) -> 6378.1
A25: Google Cloud | B25: 100GB | C25: 1.79 | G25: End of month forecast left | H25: =minus(H19,H24) -> 559.93
A26: LinkedIn Premium | C26: 0
A27: Pokpok | C27: 0
A28: Apple iPhone | B28: Paid back by Nadia 29.14 | C28: 0
A29: Alfurat | B29: Alfurat School, Barclays Bank, Account No: 73456072, Sort Code 20-84-20 (Adam Amer ref, £170 + £22 | C29: 170
A31: Extras (home improvements, shopping, gifts, etc) | E31: =sum(C32:C90) -> 1236.08
A32: Dyson | B32: Payment 3/3 | C32: 30 | D32: home-improvements
A33: Lululemon | B33: 235.8 - 129.6 | C33: 106.2 | D33: nadia
A34: Adidas | B34: 326 - 303 refund | C34: 23 | D34: aaron
A35: Haute Flourist | B35: Payment 3/3 | C35: 24.84 | D35: nadia
A36: Misuenos Kids | B36: Payment 3/3 | C36: 6.99 | D36: aaron
A37: Kidzly | B37: Payment 3/3 | C37: 6.66 | D37: aaron
A38: Boots | B38: Payment 3/3 | C38: 9.5 | D38: nadia
A39: Nike | B39: Payment 2/3 | C39: 26.66 | D39: nadia
A40: NOTHS | B40: Payment 2/3 | C40: 10.93 | D40: nadia
A41: Salomon | B41: Payment 2/3 | C41: 43.5 | D41: mohamed
...

Sheet Week 1
A1: Grocery
A2: Poundstretcher | C2: 7.25 | D2: weekly-extra
A3: Sainsbury's | C3: 25.74 | D3: weekly
A4: M&S | C4: 2.3 | D4: weekly-extra
A5: Tesco | C5: 0.75 | D5: weekly-extra
A6: Village Baker | C6: 6.25 | D6: weekly-extra
A7: M&S | C7: 16.15 | D7: weekly-extra
A8: Trinco | C8: 3.32 | D8: weekly-extra
A9: M&S | C9: 21.95 | D9: weekly
A10: Sutton Food Centre | C10: 8.03 | D10: weekly
A11: Trinco | C11: 3.32 | D11: weekly-extra
A12: M&S | C12: 27.3 | D12: weekly
A13: sMart Oriental | C13: 10.77 | D13: weekly-extra
A14: Trinco | C14: 5.63 | D14: weekly-extra
A15: M&S | B15: 8.25 + 9.2 | C15: 17.45 | D15: weekly-extra
A16: Boots | C16: 15.58 | D16: weekly-extra
A17: Sainsbury | C17: 9.54 | D17: weekly-extra
A18: M&S | C18: 24.2 | D18: weekly
A19: Trinco | C19: 6.75 | D19: holiday
A20: Greggs | C20: 4.05 | D20: holiday
C24: =sum(C2:C23) -> 216.33 | D24: Total | G24: Week total | H24: =sum(C24,C43,C58) -> 397.3
C25: =minus(100,C24) -> -116.33 | D25: GBP 100 budgeted | G25: GBP 260 budgeted p.w. | H25: =minus(260,H24) -> -137.3
A27: Weekend
A28: Popeyes | C28: 18.77 | D28: weekend-0
A29: Astrid Bakery | B29: 21.4 + 10 | C29: 31.4 | D29: weekend-1
A30: Ally Pally | B30: Car racing making for kids | C30: 21 | D30: weekend-1
A31: Ally Pally | B31: Cafe 2 + 1 | C31: 3 | D31: weekend-1
A32: Knot | C32: 8.95 | D32: weekend-1
A33: M&S | C33: 2.1 | D33: weekend-1
A34: Britannia Leisure Centre | C34: 13.9 | D34: weekend-2
A35: Britannia Leisure Centre | B35: 6.4 + 2 | C35: 8.4 | D35: weekend-2
A36: BKK Box | C36: 12 | D36: weekend-2
A37: Leigh's | B37: 12.75 + 7 | C37: 19.75 | D37: weekend-2
A38: Sourdough Sofia | C38: 16.5 | D38: weekend-2
C43: =sum(C28:C42) -> 155.77 | D43: Total
C44: =minus(100,C43) -> -55.77 | D44: GBP 100 budgeted
A46: Transport
A47: TFL | B47: Going to Alexandra palace | C47: 12.6 | D47: weekend
A48: TFL | B48: Going to Britannia leisure centre | C48: 12.6 | D48: weekend
C58: =sum(C47:C57) -> 25.2 | D58: Total
...

Sheet Week 2
A1: Grocery
A2: Pret A Manger | C2: 8.94 | D2: holiday
A3: Lidl | C3: 2.14 | D3: holiday
A4: Greggs | C4: 2.7 | D4: holiday
A5: Morden Hall Park | B5: Cafe | C5: 15.5 | D5: holiday
A6: Sainsbury | C6: 38.94 | D6: weekly
A7: M&S | C7: 35.3 | D7: weekly
A8: sMart Oriental | C8: 5.77 | D8: weekly
A9: Sutton Food Centre | C9: 6.6 | D9: weekly-extra
A10: Trinco | B10: 2.95 + 9.62 | C10: 12.57 | D10: weekly-extra
A11: M&S | C11: 4.9 | D11: weekly
A12: Rosslyn | C12: 4.3 | D12: weekly-extra
A13: M&S | B13: 6.95 + 6.8 | C13: 13.75 | D13: weekly
A14: Lidl | B14: 3.1 + 2.3 | C14: 5.4 | D14: weekly
A15: Greggs | C15: 4.05 | D15: weekly-extra
A16: Trinco | B16: 8.95 + 3.4 | C16: 12.35 | D16: weekly-extra
A17: M&S | B17: 3.9 + 12.67 | C17: 16.57 | D17: weekly
A18: Lidl | C18: 3.99 | D18: weekly
A19: Greggs | C19: 2.7 | D19: weekly-extra
C24: =sum(C2:C23) -> 196.47 | D24: Total | G24: Week total | H24: =sum(C24,C43,C54) -> 333.91
C25: =minus(100,C24) -> -96.47 | D25: GBP 100 budgeted | G25: GBP 260 budgeted p.w. | H25: =minus(260,H24) -> -73.91
A27: Weekend
A28: Popeyes | C28: 13.46 | D28: weekend-0
A29: M&S | C29: 7.5 | D29: weekend-0
A30: Kidspace | C30: 38.5 | D30: weekend-1
A31: Kidspace | B31: Cafe 3.95 + 5.2 + 3.9 + 4.4 | C31: 17.45 | D31: weekend-1
A32: M&S | C32: 19.9 | D32: weekend-1
A33: Sutton Food Centre | C33: 7.03 | D33: weekend-1
A34: Trinco | B34: 13 + 2 | C34: 15 | D34: weekend
C43: =sum(C28:C42) -> 118.84 | D43: Total
C44: =minus(100,C43) -> -18.84 | D44: GBP 100 budgeted
A46: Transport
A47: TFL | B47: Going to Morden hall park | C47: 3.5 | D47: holiday
A48: TFL | B48: Going to tradeweb | C48: 15.1 | D48: weekday
C54: =sum(C47:C53) -> 18.6 | D54: Total
C55: =minus(60,C54) -> 41.4 | D55: GBP 60 budgeted

Sheet Week 3
A1: Grocery
A2: Sainsbury | C2: 27.42 | D2: weekly
A3: M&S | C3: 10.95 | D3: weekly
A4: Sutton Food Centre | C4: 24.71 | D4: weekly
A5: Dynamic Local | C5: 3.3 | D5: weekly
A6: Scenery | C6: 8.9 | D6: weekly-extra
A7: Lidl | C7: 2.44 | D7: weekly-extra
A8: M&S | C8: 39.72 | D8: weekly
A9: Trinco | C9: 3.32 | D9: weekly-extra
A10: Kamsons | C10: 9.9 | D10: weekly-extra
A11: La Peche | C11: 27.75 | D11: weekly-extra
A12: Trinco | C12: 2.95 | D12: weekly-extra
A13: M&S | C13: 8 | D13: weekly-extra
... A15: Popeyes | C15: 6.98 | D15: weekly-extra
C21: =sum(C2:C20) -> 178.43 | D21: Total | G21: Week total | H21: =sum(C21,C37,C57) -> 312.41
C22: =minus(100,C21) -> -78.43 | D22: GBP 100 budgeted | G22: GBP 260 budgeted p.w. | H22: =minus(260,H21) -> -52.41
A24: Weekend
A25: Popeyes | C25: 14.45 | D25: weekend-0
A26: M&S | B26: 14.45 + 4 | C26: 18.45 | D26: weekend-0
A27: NOT | C27: 2 | D27: weekend-0
A28: By Anna | C28: 3.3 | D28: weekend-1
A29: Kokoro | C29: 4.75 | D29: weekend-1
A30: M&S | C30: 9.3 | D30: weekend-1
A31: Lidl | C31: 2.86 | D31: weekend-1
A32: Trinco | C32: 19.64 | D32: weekend-2
A33: Sutton Food Centre | C33: 28.58 | D33: weekend-2
A34: Tesco | C34: 2.35 | D34: weekend-2
C37: =sum(C25:C36) -> 105.68 | D37: Total
C38: =minus(100,C37) -> -5.68 | D38: GBP 100 budgeted
A40: Transport
A41: TFL | B41: Going to work | C41: 13.2 | D41: weekday
A42: TFL | B42: Going to work | C42: 15.1 | D42: weekday
C57: =sum(C41:C56) -> 28.3 | D57: Total
C58: =minus(60,C57) -> 31.7 | D58: GBP 60 budgeted

Sheet Week 4
A1: Grocery
A2: Boots | C2: 5 | D2: weekly-extra
A3: Sainsbury | C3: 34.44 | D3: weekly-extra
A4: M&S | B4: 26.25 + 9.35 | C4: 35.6 | D4: weekly
A5: Greggs | C5: 4.4 | D5: weekly-extra
A6: Trinco | C6: 3.32 | D6: weekly-extra
A7: M&S | B7: 10.55 + 29.75 + 0.9 | C7: 41.2 | D7: weekly-extra
A8: Boots | C8: 1.1 | D8: weekly-extra
A9: Trinco | C9: 2.95 | D9: weekly-extra
A10: Greggs | C10: 4.05 | D10: weekly-extra
A11: Trinco | C11: 18.29 | D11: weekly-extra
A12: Lidl | C12: 3.82 | D12: weekly-extra
C28: =sum(C2:C27) -> 154.17 | D28: Total | G28: Week total | H28: =sum(C28,C43,C57) -> 278.52
C29: =minus(100,C28) -> -54.17 | D29: GBP 100 budgeted | G29: GBP 260 budgeted p.w. | H29: =minus(260,H28) -> -18.52
A31: Weekend
A32: Popeyes | C32: 6.98 | D32: weekend-0
A33: Sutton Food Centre | C33: 3.72 | D33: weekend-0
A34: Bourne Hall | B34: Cafe | C34: 2.5 | D34: weekend-1
A35: M&S | B35: 22.3 + 20.45 | C35: 42.75 | D35: weekend-1
A36: Co-op | C36: 4.5 | D36: weekend-2
A37: Trinco | B37: 9.91 + 17.38 | C37: 27.29 | D37: weekend-2
A38: Greggs | C38: 4.05 | D38: weekend-2
C43: =sum(C32:C42) -> 91.79 | D43: Total
C44: =minus(100,C43) -> 8.21 | D44: GBP 100 budgeted
A46: Transport
A47: TFL | B47: Going to work meeting | C47: 11 | D47: weekday
A48: TFL | B48: Train to Ewel east to pick adam and Zak | C48: 3 | D48: weekend
A49: Uber | B49: Getting adam and Zak back from Arabic school | C49: 18.56 | D49: weekend
C57: =sum(C47:C56) -> 32.56 | D57: Total
C58: =minus(60,C57) -> 27.44 | D58: GBP 60 budgeted

Sheet Week 5
A1: Grocery
A2: Sainsbury | C2: 40.18 | D2: weekly
A3: Sutton Food Centre | C3: 29.38 | D3: weekly
A4: M&S | B4: 1 + 12.85 | C4: 13.85 | D4: weekly
A5: Lidl | B5: 2.78 + 1.59 | C5: 4.37 | D5: weekly
A6: M&S | B6: 12.95 + 9.35 + 1.1 | C6: 23.4 | D6: weekly
A7: Lidl | C7: 1.59 | D7: weekly
A8: Trinco | C8: 3.32 | D8: weekly-extra
A9: M&S | B9: 2.5 + 7.55 | C9: 10.05 | D9: weekly
A10: Trinco | C10: 3.32 | D10: weekly-extra
A11: Sutton Food Centre | C11: 12.51 | D11: weekly
C28: =sum(C2:C27) -> 141.97 | D28: Total | G28: Week total | H28: =sum(C28,C43,C57) -> 241.26
C29: =minus(100,C28) -> -41.97 | D29: GBP 100 budgeted | G29: GBP 260 budgeted p.w. | H29: =minus(260,H28) -> 18.74
A31: Weekend
A32: Kokoro | C32: 7.35 | D32: weekend-0
A33: Popeyes | C33: 8.47 | D33: weekend-0
A34: Greggs | C34: 2.7 | D34: weekend-0
A35: Trinco | B35: 8.22 + 3.4 + 7.5 | C35: 19.12 | D35: weekend-1
A36: H Samuel | B36: Cancer free muffin | C36: 2.5 | D36: weekend-1
A37: Nando's | C37: 22.48 | D37: weekend-1
A38: M&S | C38: 28.47 | D38: weekend-1
A39: Co-op | C39: 8.2 | D39: weekend-2
C43: =sum(C32:C42) -> 99.29 | D43: Total
C44: =minus(100,C43) -> 0.71 | D44: GBP 100 budgeted
A46: Transport
C57: =sum(C47:C56) -> 0 | D57: Total
C58: =minus(60,C57) -> 60 | D58: GBP 60 budgeted
